Traceback (most recent call last):
  File "/usr/lib/python3.10/runpy.py", line 196, in _run_module_as_main
    return _run_code(code, main_globals, None,
  File "/usr/lib/python3.10/runpy.py", line 86, in _run_code
    exec(code, run_globals)
  File "/home/cgume/SOA/users_service/infrastructure/rabbitmq_consumer.py", line 33, in <module>
    start_user_consumer()
  File "/home/cgume/SOA/users_service/infrastructure/rabbitmq_consumer.py", line 19, in start_user_consumer
    connection = pika.BlockingConnection(pika.ConnectionParameters(host=RABBITMQ_HOST, credentials=credentials))
  File "/home/cgume/.local/lib/python3.10/site-packages/pika/adapters/blocking_connection.py", line 360, in __init__
    self._impl = self._create_connection(parameters, _impl_class)
  File "/home/cgume/.local/lib/python3.10/site-packages/pika/adapters/blocking_connection.py", line 451, in _create_connection
    raise self._reap_last_connection_workflow_error(error)
pika.exceptions.IncompatibleProtocolError: StreamLostError: ("Stream connection lost: ConnectionResetError(104, 'Connection reset by peer')",)
Traceback (most recent call last):
  File "/usr/lib/python3.10/runpy.py", line 196, in _run_module_as_main
    return _run_code(code, main_globals, None,
  File "/usr/lib/python3.10/runpy.py", line 86, in _run_code
    exec(code, run_globals)
  File "/home/cgume/SOA/users_service/infrastructure/rabbitmq_consumer.py", line 33, in <module>
    start_user_consumer()
  File "/home/cgume/SOA/users_service/infrastructure/rabbitmq_consumer.py", line 19, in start_user_consumer
    connection = pika.BlockingConnection(pika.ConnectionParameters(host=RABBITMQ_HOST, credentials=credentials))
  File "/home/cgume/.local/lib/python3.10/site-packages/pika/adapters/blocking_connection.py", line 360, in __init__
    self._impl = self._create_connection(parameters, _impl_class)
  File "/home/cgume/.local/lib/python3.10/site-packages/pika/adapters/blocking_connection.py", line 451, in _create_connection
    raise self._reap_last_connection_workflow_error(error)
pika.exceptions.IncompatibleProtocolError: StreamLostError: ("Stream connection lost: ConnectionResetError(104, 'Connection reset by peer')",)
Traceback (most recent call last):
  File "/usr/lib/python3.10/runpy.py", line 196, in _run_module_as_main
    return _run_code(code, main_globals, None,
  File "/usr/lib/python3.10/runpy.py", line 86, in _run_code
    exec(code, run_globals)
  File "/home/cgume/SOA/users_service/infrastructure/rabbitmq_consumer.py", line 33, in <module>
    start_user_consumer()
  File "/home/cgume/SOA/users_service/infrastructure/rabbitmq_consumer.py", line 19, in start_user_consumer
    connection = pika.BlockingConnection(pika.ConnectionParameters(host=RABBITMQ_HOST, credentials=credentials))
  File "/home/cgume/.local/lib/python3.10/site-packages/pika/adapters/blocking_connection.py", line 360, in __init__
    self._impl = self._create_connection(parameters, _impl_class)
  File "/home/cgume/.local/lib/python3.10/site-packages/pika/adapters/blocking_connection.py", line 451, in _create_connection
    raise self._reap_last_connection_workflow_error(error)
pika.exceptions.IncompatibleProtocolError: StreamLostError: ('Transport indicated EOF',)
Traceback (most recent call last):
  File "/usr/lib/python3.10/runpy.py", line 196, in _run_module_as_main
    return _run_code(code, main_globals, None,
  File "/usr/lib/python3.10/runpy.py", line 86, in _run_code
    exec(code, run_globals)
  File "/home/cgume/SOA/users_service/infrastructure/rabbitmq_consumer.py", line 33, in <module>
    start_user_consumer()
  File "/home/cgume/SOA/users_service/infrastructure/rabbitmq_consumer.py", line 19, in start_user_consumer
    connection = pika.BlockingConnection(pika.ConnectionParameters(host=RABBITMQ_HOST, credentials=credentials))
  File "/home/cgume/.local/lib/python3.10/site-packages/pika/adapters/blocking_connection.py", line 360, in __init__
    self._impl = self._create_connection(parameters, _impl_class)
  File "/home/cgume/.local/lib/python3.10/site-packages/pika/adapters/blocking_connection.py", line 451, in _create_connection
    raise self._reap_last_connection_workflow_error(error)
pika.exceptions.IncompatibleProtocolError: StreamLostError: ("Stream connection lost: ConnectionResetError(104, 'Connection reset by peer')",)
Traceback (most recent call last):
  File "/usr/lib/python3.10/runpy.py", line 196, in _run_module_as_main
    return _run_code(code, main_globals, None,
  File "/usr/lib/python3.10/runpy.py", line 86, in _run_code
    exec(code, run_globals)
  File "/home/cgume/SOA/users_service/infrastructure/rabbitmq_consumer.py", line 33, in <module>
    start_user_consumer()
  File "/home/cgume/SOA/users_service/infrastructure/rabbitmq_consumer.py", line 19, in start_user_consumer
    connection = pika.BlockingConnection(pika.ConnectionParameters(host=RABBITMQ_HOST, credentials=credentials))
  File "/home/cgume/.local/lib/python3.10/site-packages/pika/adapters/blocking_connection.py", line 360, in __init__
    self._impl = self._create_connection(parameters, _impl_class)
  File "/home/cgume/.local/lib/python3.10/site-packages/pika/adapters/blocking_connection.py", line 451, in _create_connection
    raise self._reap_last_connection_workflow_error(error)
pika.exceptions.IncompatibleProtocolError: StreamLostError: ('Transport indicated EOF',)
Traceback (most recent call last):
  File "/usr/lib/python3.10/runpy.py", line 196, in _run_module_as_main
    return _run_code(code, main_globals, None,
  File "/usr/lib/python3.10/runpy.py", line 86, in _run_code
    exec(code, run_globals)
  File "/home/cgume/SOA/users_service/infrastructure/rabbitmq_consumer.py", line 33, in <module>
    start_user_consumer()
  File "/home/cgume/SOA/users_service/infrastructure/rabbitmq_consumer.py", line 19, in start_user_consumer
    connection = pika.BlockingConnection(pika.ConnectionParameters(host=RABBITMQ_HOST, credentials=credentials))
  File "/home/cgume/.local/lib/python3.10/site-packages/pika/adapters/blocking_connection.py", line 360, in __init__
    self._impl = self._create_connection(parameters, _impl_class)
  File "/home/cgume/.local/lib/python3.10/site-packages/pika/adapters/blocking_connection.py", line 451, in _create_connection
    raise self._reap_last_connection_workflow_error(error)
pika.exceptions.IncompatibleProtocolError: StreamLostError: ('Transport indicated EOF',)
Traceback (most recent call last):
  File "/usr/lib/python3.10/runpy.py", line 196, in _run_module_as_main
    return _run_code(code, main_globals, None,
  File "/usr/lib/python3.10/runpy.py", line 86, in _run_code
    exec(code, run_globals)
  File "/home/cgume/SOA/users_service/infrastructure/rabbitmq_consumer.py", line 33, in <module>
    start_user_consumer()
  File "/home/cgume/SOA/users_service/infrastructure/rabbitmq_consumer.py", line 19, in start_user_consumer
    connection = pika.BlockingConnection(pika.ConnectionParameters(host=RABBITMQ_HOST, credentials=credentials))
  File "/home/cgume/.local/lib/python3.10/site-packages/pika/adapters/blocking_connection.py", line 360, in __init__
    self._impl = self._create_connection(parameters, _impl_class)
  File "/home/cgume/.local/lib/python3.10/site-packages/pika/adapters/blocking_connection.py", line 451, in _create_connection
    raise self._reap_last_connection_workflow_error(error)
pika.exceptions.IncompatibleProtocolError: StreamLostError: ('Transport indicated EOF',)
Traceback (most recent call last):
  File "/usr/lib/python3.10/runpy.py", line 196, in _run_module_as_main
    return _run_code(code, main_globals, None,
  File "/usr/lib/python3.10/runpy.py", line 86, in _run_code
    exec(code, run_globals)
  File "/home/cgume/SOA/users_service/infrastructure/rabbitmq_consumer.py", line 33, in <module>
    start_user_consumer()
  File "/home/cgume/SOA/users_service/infrastructure/rabbitmq_consumer.py", line 29, in start_user_consumer
    channel.start_consuming()
  File "/home/cgume/.local/lib/python3.10/site-packages/pika/adapters/blocking_connection.py", line 1883, in start_consuming
    self._process_data_events(time_limit=None)
  File "/home/cgume/.local/lib/python3.10/site-packages/pika/adapters/blocking_connection.py", line 2044, in _process_data_events
    self.connection.process_data_events(time_limit=time_limit)
  File "/home/cgume/.local/lib/python3.10/site-packages/pika/adapters/blocking_connection.py", line 842, in process_data_events
    self._flush_output(common_terminator)
  File "/home/cgume/.local/lib/python3.10/site-packages/pika/adapters/blocking_connection.py", line 523, in _flush_output
    raise self._closed_result.value.error
pika.exceptions.ConnectionClosedByBroker: (320, "CONNECTION_FORCED - broker forced connection closure with reason 'shutdown'")
 [*] Esperando mensajes en la cola 'users_queue'. Presiona CTRL+C para salir.
 [x] Recibido mensaje en la cola 'users_queue': b"{'operation': 'create', 'data': {'name': 'hexatlon13', 'email': 'john@example.com', 'id': 'edeef9a5-0e8b-42a1-9348-7a6fbfa218ba', '_id': '24b0a2f1-29b5-4f7c-b29f-7e5fc29faf07'}}"
Traceback (most recent call last):
  File "/usr/lib/python3.10/runpy.py", line 196, in _run_module_as_main
    return _run_code(code, main_globals, None,
  File "/usr/lib/python3.10/runpy.py", line 86, in _run_code
    exec(code, run_globals)
  File "/home/cgume/SOA/users_service/infrastructure/rabbitmq_consumer.py", line 33, in <module>
    start_user_consumer()
  File "/home/cgume/SOA/users_service/infrastructure/rabbitmq_consumer.py", line 19, in start_user_consumer
    connection = pika.BlockingConnection(pika.ConnectionParameters(host=RABBITMQ_HOST, credentials=credentials))
  File "/home/cgume/.local/lib/python3.10/site-packages/pika/adapters/blocking_connection.py", line 360, in __init__
    self._impl = self._create_connection(parameters, _impl_class)
  File "/home/cgume/.local/lib/python3.10/site-packages/pika/adapters/blocking_connection.py", line 451, in _create_connection
    raise self._reap_last_connection_workflow_error(error)
pika.exceptions.IncompatibleProtocolError: StreamLostError: ('Transport indicated EOF',)
Traceback (most recent call last):
  File "/usr/lib/python3.10/runpy.py", line 196, in _run_module_as_main
    return _run_code(code, main_globals, None,
  File "/usr/lib/python3.10/runpy.py", line 86, in _run_code
    exec(code, run_globals)
  File "/home/cgume/SOA/users_service/infrastructure/rabbitmq_consumer.py", line 33, in <module>
    start_user_consumer()
  File "/home/cgume/SOA/users_service/infrastructure/rabbitmq_consumer.py", line 19, in start_user_consumer
    connection = pika.BlockingConnection(pika.ConnectionParameters(host=RABBITMQ_HOST, credentials=credentials))
  File "/home/cgume/.local/lib/python3.10/site-packages/pika/adapters/blocking_connection.py", line 360, in __init__
    self._impl = self._create_connection(parameters, _impl_class)
  File "/home/cgume/.local/lib/python3.10/site-packages/pika/adapters/blocking_connection.py", line 451, in _create_connection
    raise self._reap_last_connection_workflow_error(error)
pika.exceptions.IncompatibleProtocolError: StreamLostError: ('Transport indicated EOF',)
Traceback (most recent call last):
  File "/usr/lib/python3.10/runpy.py", line 196, in _run_module_as_main
    return _run_code(code, main_globals, None,
  File "/usr/lib/python3.10/runpy.py", line 86, in _run_code
    exec(code, run_globals)
  File "/home/cgume/SOA/users_service/infrastructure/rabbitmq_consumer.py", line 33, in <module>
    start_user_consumer()
  File "/home/cgume/SOA/users_service/infrastructure/rabbitmq_consumer.py", line 19, in start_user_consumer
    connection = pika.BlockingConnection(pika.ConnectionParameters(host=RABBITMQ_HOST, credentials=credentials))
  File "/home/cgume/.local/lib/python3.10/site-packages/pika/adapters/blocking_connection.py", line 360, in __init__
    self._impl = self._create_connection(parameters, _impl_class)
  File "/home/cgume/.local/lib/python3.10/site-packages/pika/adapters/blocking_connection.py", line 451, in _create_connection
    raise self._reap_last_connection_workflow_error(error)
pika.exceptions.IncompatibleProtocolError: StreamLostError: ('Transport indicated EOF',)
Traceback (most recent call last):
  File "/usr/lib/python3.10/runpy.py", line 196, in _run_module_as_main
    return _run_code(code, main_globals, None,
  File "/usr/lib/python3.10/runpy.py", line 86, in _run_code
    exec(code, run_globals)
  File "/home/cgume/SOA/users_service/infrastructure/rabbitmq_consumer.py", line 33, in <module>
    start_user_consumer()
  File "/home/cgume/SOA/users_service/infrastructure/rabbitmq_consumer.py", line 19, in start_user_consumer
    connection = pika.BlockingConnection(pika.ConnectionParameters(host=RABBITMQ_HOST, credentials=credentials))
  File "/home/cgume/.local/lib/python3.10/site-packages/pika/adapters/blocking_connection.py", line 360, in __init__
    self._impl = self._create_connection(parameters, _impl_class)
  File "/home/cgume/.local/lib/python3.10/site-packages/pika/adapters/blocking_connection.py", line 451, in _create_connection
    raise self._reap_last_connection_workflow_error(error)
pika.exceptions.IncompatibleProtocolError: StreamLostError: ('Transport indicated EOF',)
